<?xml version="1.0" encoding="utf-8"?>
<!-- =================================================================================== -->
<!--   Copyright 2020 ANYbotics, https://www.anybotics.com                               -->
<!-- =================================================================================== -->
<!-- This file contains the description of the ANYmal C robot. -->
<robot name="anymal">
    <!-- Base link -->
    <link name="base">
        <visual>
            <origin rpy="0 0 0" xyz="0 0 0"/>
            <geometry>
                <box size = "0.02 0.015 0.5e-3"/>
            </geometry>
            <material name="Cyan">
                <color rgba="1.0 1.0 1.0 1.0"/>
            </material>
        </visual>
        <collision>
            <origin rpy="0 0 0" xyz="0 0 0"/>
            <geometry>
                <box size = "0.02 0.015 0.013"/>
            </geometry>
        </collision>
        <inertial>
            <origin xyz="0 0 0" rpy="0 0 0"/>
            <mass value="0.539e-3"/>
            <!-- <inertia 
                ixx="31.301e-9"  
                ixy="0"  
                ixz="0" 
                iyy="41.279e-9" 
                iyz="0" 
                izz="36.6e-9" /> -->
        </inertial>
    </link>
    <joint name="base_base_left" type="fixed">
        <parent link="base"/>
        <child link="base_left"/>
        <origin rpy="-1.5707963268 0 0" xyz="0 -0.0075 -0.001"/>
    </joint>

    <link name="base_left">
        <visual>
            <origin rpy="0 0 0" xyz="0 0 15e-3"/>
            <geometry>
                <box size = "0.02 0.015 0.5e-3"/>
            </geometry>
            <material name="Cyan">
                <color rgba="1.0 1.0 1.0 1.0"/>
            </material>
        </visual>
        <inertial>
            <origin xyz="0 0 0" rpy="0 0 0"/>
            <mass value="0.15e-3"/>
            <!-- <inertia 
                ixx="2.82e-9"  
                ixy="0"  
                ixz="0" 
                iyy="7.81e-9" 
                iyz="0" 
                izz="5.00e-9" /> -->
        </inertial>
    </link>

    <joint name="base_base_right" type="fixed">
        <parent link="base"/>
        <child link="base_right"/>
        <origin rpy="-1.5707963268 0 0.0" xyz="0 -0.0225 -0.001"/>
    </joint>

    <link name="base_right">
        <visual>
            <origin rpy="0 0 0" xyz="0 0 15e-3"/>
            <geometry>
                <box size = "0.02 0.015 0.5e-3"/>
            </geometry>
            <material name="Cyan">
                <color rgba="1.0 1.0 1.0 1.0"/>
            </material>
        </visual>
        <inertial>
            <origin xyz="0 0 0" rpy="0 0 0"/>
            <mass value="0.15e-3"/>
            <!-- <inertia 
                ixx="2.82e-9"  
                ixy="0"  
                ixz="0" 
                iyy="7.81e-9" 
                iyz="0" 
                izz="5.00e-9" /> -->
        </inertial>
    </link>


    <!--              -->
    <!-- Left Front Leg -->
    <!--              -->

    <!-- [rad] -->
    <!-- joint base HAA -->
    <joint name="base_LF_HFE" type="fixed">
        <parent link="base_left"/>
        <child link="LF_HFE"/>
        <origin rpy="0 0 3.34159265359" xyz="-0.0065 0.0055 0.0155"/>
    </joint>
    <!-- [m] -->
    <!-- [A] -->
    <!-- Drive Input Link -->
    <link name="LF_HFE">
        <visual>
            <origin rpy="0 0 0" xyz="0 0 0"/>
            <geometry>
                <cylinder length="0.5e-3" radius="0.25e-3"/>
            </geometry>
            <material name="Red">
                <color rgba="1.0 0.0 0.0 1.0"/>
            </material>
        </visual>
    </link>
    <!-- joint Drive output -->
    <joint name="LF_HFE" type="revolute">
        <parent link="LF_HFE"/>
        <child link="LF_THIGH"/>
        <origin rpy="0 0 0" xyz="0 0 0"/>
        <axis xyz="0 0 1"/>
        <limit effort="80.0" velocity="20." lower="-0.2" upper="0.2"/>
        <dynamics damping="0.0" friction="0.0"/>
    </joint>
    <!-- Drive Output Link -->
    <link name="LF_THIGH">
        <visual>
            <origin rpy="0 0 0" xyz="0 0 0"/>
            <geometry>
                <cylinder length="0.5e-3" radius="0.25e-3"/>
            </geometry>
            <material name="Red">
                <color rgba="1.0 0.0 0.0 0.8"/>
            </material>
        </visual>
    </link>
    <joint name="LF_THIGH_LF_THIGH_fixed" type="fixed">
        <parent link="LF_THIGH"/>
        <child link="LF_THIGH_fixed"/>
        <origin rpy="0 0 1.5707963268" xyz="0 -1.5e-3 0"/>
    </joint>
    <link name="LF_THIGH_fixed">
        <visual>
            <origin rpy="0 0 0" xyz="0 0 0"/>
            <geometry>
                <box size = "3e-3 1e-3 0.5e-3"/>
            </geometry>
            <material name="Blue">
                <color rgba="0.0 0.0 1.0 0.8"/>
            </material>
        </visual>
        <inertial>
            <origin rpy="0 0 0" xyz="0 0 0"/>
            <mass value="0.002e-9"/>
        <!-- <inertia 
            ixx="0.002e-9" 
            ixy="0" 
            ixz="0" 
            iyy="0.002e-9" 
            iyz="0" 
            izz="0.002e-9"/> -->
        </inertial>
    </link>
    <joint name="LF_THIGH_fixed_LF_KFE" type="fixed">
        <parent link="LF_THIGH_fixed"/>
        <child link="LF_KFE"/>
        <origin rpy="0 0 0.5235987756" xyz="-1.5e-3 0 0"/>
    </joint>
    <!-- [m] -->
    <!-- [A] -->
    <!-- Drive Input Link -->
    <link name="LF_KFE">
        <visual>
            <origin rpy="0 0 0" xyz="0 0 0"/>
            <geometry>
                <cylinder length="0.5e-3" radius="0.25e-3"/>
            </geometry>
            <material name="Red">
                <color rgba="1.0 0.0 0.0 0.8"/>
            </material>
        </visual>
        <collision>
            <origin rpy="0 0 0" xyz="0 0 0"/>
            <geometry>
                <cylinder length="0.5e-3" radius="0.25e-3"/>
            </geometry>
        </collision>
    </link>
    <!-- joint Drive output -->
    <joint name="LF_KFE" type="revolute">
        <parent link="LF_KFE"/>
        <child link="LF_SHANK"/>
        <origin rpy="0 0 0" xyz="0 0 0"/>
        <axis xyz="0 0 1"/>
        <limit effort="80.0" velocity="20." lower="-0.2" upper="0.2"/>
        <dynamics damping="0.0" friction="0.0"/>
    </joint>
    <!-- Drive Output Link -->
    <link name="LF_SHANK">
        <visual>
            <origin rpy="0 0 0" xyz="0 0 0"/>
            <geometry>
                <cylinder length="0.5e-3" radius="0.25e-3"/>
            </geometry>
            <material name="Red">
                <color rgba="1.0 0.0 0.0 0.8"/>
            </material>
        </visual>
    </link>
    <joint name="LF_SHANK_LF_SHANK_fixed" type="fixed">
        <parent link="LF_SHANK"/>
        <child link="LF_SHANK_fixed"/>
        <origin rpy="0 0 1.5707963268" xyz="0 1.5e-3 0"/>
    </joint>
    <link name="LF_SHANK_fixed">
        <visual>
            <origin rpy="0 0 0" xyz="0 0 0"/>
            <geometry>
                <box size = "3e-3 1e-3 0.5e-3"/>
            </geometry>
            <material name="Blue">
                <color rgba="0.0 0.0 1.0 0.8"/>
            </material>
        </visual>
        <inertial>
            <origin rpy="0 0 0" xyz="0 0 0"/>
            <mass value="0.002e-9"/>
        <!-- <inertia 
            ixx="0.002e-9" 
            ixy="0" 
            ixz="0" 
            iyy="0.002e-9" 
            iyz="0" 
            izz="0.002e-9"/> -->
        </inertial>
    </link>
    <joint name="LF_SHANK_fixed_LF_Foot" type="fixed">
        <parent link="LF_SHANK_fixed"/>
        <child link="LF_Foot"/>
        <origin rpy="0 0 1.5707963268" xyz="1.5e-3 0 0"/>
    </joint>
    <link name="LF_Foot">
        <visual>
            <origin rpy="0 0 0" xyz="0 0 0"/>
            <geometry>
                <cylinder length="1e-3" radius="0.6e-3"/>
            </geometry>
            <material name="Red">
                <color rgba="1.0 0.0 0.0 0.8"/>
            </material>
        </visual>
        <collision>
            <origin rpy="0 0 0" xyz="0 0 0"/>
            <geometry>
                <cylinder length="1e-3" radius="0.6e-3"/>
            </geometry>
        </collision>
    </link>



    <!--              -->
    <!-- Left Hind Leg -->
    <!--              -->

    <!-- [rad] -->
    <!-- joint base HAA -->
    <joint name="base_LH_HFE" type="fixed">
        <parent link="base_left"/>
        <child link="LH_HFE"/>
        <origin rpy="0 0 2.9415926535" xyz="0.0065 0.0055 0.0155"/>
    </joint>
    <!-- [m] -->
    <!-- [A] -->
    <!-- Drive Input Link -->
    <link name="LH_HFE">
        <visual>
            <origin rpy="0 0 0" xyz="0 0 0"/>
            <geometry>
                <cylinder length="0.5e-3" radius="0.25e-3"/>
            </geometry>
            <material name="Red">
                <color rgba="1.0 0.0 0.0 1.0"/>
            </material>
        </visual>
    </link>
    <!-- joint Drive output -->
    <joint name="LH_HFE" type="revolute">
        <parent link="LH_HFE"/>
        <child link="LH_THIGH"/>
        <origin rpy="0 0 0" xyz="0 0 0"/>
        <axis xyz="0 0 1"/>
        <limit effort="80.0" velocity="20." lower="-0.2" upper="0.2"/>
        <dynamics damping="0.0" friction="0.0"/>
    </joint>
    <!-- Drive Output Link -->
    <link name="LH_THIGH">
        <visual>
            <origin rpy="0 0 0" xyz="0 0 0"/>
            <geometry>
                <cylinder length="0.5e-3" radius="0.25e-3"/>
            </geometry>
            <material name="Red">
                <color rgba="1.0 0.0 0.0 0.8"/>
            </material>
        </visual>
    </link>
    <joint name="LH_THIGH_LH_THIGH_fixed" type="fixed">
        <parent link="LH_THIGH"/>
        <child link="LH_THIGH_fixed"/>
        <origin rpy="0 0 1.5707963268" xyz="0 -1.5e-3 0"/>
    </joint>
    <link name="LH_THIGH_fixed">
        <visual>
            <origin rpy="0 0 0" xyz="0 0 0"/>
            <geometry>
                <box size = "3e-3 1e-3 0.5e-3"/>
            </geometry>
            <material name="Blue">
                <color rgba="0.0 0.0 1.0 0.8"/>
            </material>
        </visual>
        <inertial>
            <origin rpy="0 0 0" xyz="0 0 0"/>
            <mass value="0.002e-9"/>
        <!-- <inertia 
            ixx="0.002e-9" 
            ixy="0" 
            ixz="0" 
            iyy="0.002e-9" 
            iyz="0" 
            izz="0.002e-9"/> -->
        </inertial>
    </link>
    <joint name="LH_THIGH_fixed_LH_KFE" type="fixed">
        <parent link="LH_THIGH_fixed"/>
        <child link="LH_KFE"/>
        <origin rpy="0 0 2.61799387799" xyz="-1.5e-3 0 0"/>
    </joint>
    <!-- [m] -->
    <!-- [A] -->
    <!-- Drive Input Link -->
    <link name="LH_KFE">
        <visual>
            <origin rpy="0 0 0" xyz="0 0 0"/>
            <geometry>
                <cylinder length="0.5e-3" radius="0.25e-3"/>
            </geometry>
            <material name="Red">
                <color rgba="1.0 0.0 0.0 0.8"/>
            </material>
        </visual>
        <collision>
            <origin rpy="0 0 0" xyz="0 0 0"/>
            <geometry>
                <cylinder length="0.5e-3" radius="0.25e-3"/>
            </geometry>
        </collision>
    </link>
    <!-- joint Drive output -->
    <joint name="LH_KFE" type="revolute">
        <parent link="LH_KFE"/>
        <child link="LH_SHANK"/>
        <origin rpy="0 0 0" xyz="0 0 0"/>
        <axis xyz="0 0 1"/>
        <limit effort="80.0" velocity="20." lower="-0.2" upper="0.2"/>
        <dynamics damping="0.0" friction="0.0"/>
    </joint>
    <!-- Drive Output Link -->
    <link name="LH_SHANK">
        <visual>
            <origin rpy="0 0 0" xyz="0 0 0"/>
            <geometry>
                <cylinder length="0.5e-3" radius="0.25e-3"/>
            </geometry>
            <material name="Red">
                <color rgba="1.0 0.0 0.0 0.8"/>
            </material>
        </visual>
    </link>
    <joint name="LH_SHANK_LH_SHANK_fixed" type="fixed">
        <parent link="LH_SHANK"/>
        <child link="LH_SHANK_fixed"/>
        <origin rpy="0 0 1.5707963268" xyz="0 1.5e-3 0"/>
    </joint>
    <link name="LH_SHANK_fixed">
        <visual>
            <origin rpy="0 0 0" xyz="0 0 0"/>
            <geometry>
                <box size = "3e-3 1e-3 0.5e-3"/>
            </geometry>
            <material name="Blue">
                <color rgba="0.0 0.0 1.0 0.8"/>
            </material>
        </visual>
        <inertial>
            <origin rpy="0 0 0" xyz="0 0 0"/>
            <mass value="0.002e-9"/>
        <!-- <inertia 
            ixx="0.002e-9" 
            ixy="0" 
            ixz="0" 
            iyy="0.002e-9" 
            iyz="0" 
            izz="0.002e-9"/> -->
        </inertial>
    </link>
    <joint name="LH_SHANK_fixed_LH_Foot" type="fixed">
        <parent link="LH_SHANK_fixed"/>
        <child link="LH_Foot"/>
        <origin rpy="0 0 1.5707963268" xyz="1.5e-3 0 0"/>
    </joint>
    <link name="LH_Foot">
        <visual>
            <origin rpy="0 0 0" xyz="0 0 0"/>
            <geometry>
                <cylinder length="1e-3" radius="0.6e-3"/>
            </geometry>
            <material name="Red">
                <color rgba="1.0 0.0 0.0 0.8"/>
            </material>
        </visual>
        <collision>
            <origin rpy="0 0 0" xyz="0 0 0"/>
            <geometry>
                <cylinder length="1e-3" radius="0.6e-3"/>
            </geometry>
        </collision>
    </link>

    <!--              -->
    <!-- Right Front Leg -->
    <!--              -->

    <!-- [rad] -->
    <!-- joint base HAA -->
    <joint name="base_RF_HFE" type="fixed">
        <parent link="base_right"/>
        <child link="RF_HFE"/>
        <origin rpy="0 0 3.34159265359" xyz="-0.0065 0.0055 0.0145"/>
    </joint>
    <!-- [m] -->
    <!-- [A] -->
    <!-- Drive Input Link -->
    <link name="RF_HFE">
        <visual>
            <origin rpy="0 0 0" xyz="0 0 0"/>
            <geometry>
                <cylinder length="0.5e-3" radius="0.25e-3"/>
            </geometry>
            <material name="Red">
                <color rgba="1.0 0.0 0.0 1.0"/>
            </material>
        </visual>
    </link>
    <!-- joint Drive output -->
    <joint name="RF_HFE" type="revolute">
        <parent link="RF_HFE"/>
        <child link="RF_THIGH"/>
        <origin rpy="0 0 0" xyz="0 0 0"/>
        <axis xyz="0 0 1"/>
        <limit effort="80.0" velocity="20." lower="-0.2" upper="0.2"/>
        <dynamics damping="0.0" friction="0.0"/>
    </joint>
    <!-- Drive Output Link -->
    <link name="RF_THIGH">
        <visual>
            <origin rpy="0 0 0" xyz="0 0 0"/>
            <geometry>
                <cylinder length="0.5e-3" radius="0.25e-3"/>
            </geometry>
            <material name="Red">
                <color rgba="1.0 0.0 0.0 0.8"/>
            </material>
        </visual>
    </link>
    <joint name="RF_THIGH_RF_THIGH_fixed" type="fixed">
        <parent link="RF_THIGH"/>
        <child link="RF_THIGH_fixed"/>
        <origin rpy="0 0 1.5707963268" xyz="0 -1.5e-3 0"/>
    </joint>
    <link name="RF_THIGH_fixed">
        <visual>
            <origin rpy="0 0 0" xyz="0 0 0"/>
            <geometry>
                <box size = "3e-3 1e-3 0.5e-3"/>
            </geometry>
            <material name="Blue">
                <color rgba="0.0 0.0 1.0 0.8"/>
            </material>
        </visual>
        <inertial>
            <origin rpy="0 0 0" xyz="0 0 0"/>
            <mass value="0.002e-9"/>
        <!-- <inertia 
            ixx="0.002e-9" 
            ixy="0" 
            ixz="0" 
            iyy="0.002e-9" 
            iyz="0" 
            izz="0.002e-9"/> -->
        </inertial>
    </link>
    <joint name="RF_THIGH_fixed_RF_KFE" type="fixed">
        <parent link="RF_THIGH_fixed"/>
        <child link="RF_KFE"/>
        <origin rpy="0 0 0.5235987756" xyz="-1.5e-3 0 0"/>
    </joint>
    <!-- [m] -->
    <!-- [A] -->
    <!-- Drive Input Link -->
    <link name="RF_KFE">
        <visual>
            <origin rpy="0 0 0" xyz="0 0 0"/>
            <geometry>
                <cylinder length="0.5e-3" radius="0.25e-3"/>
            </geometry>
            <material name="Red">
                <color rgba="1.0 0.0 0.0 0.8"/>
            </material>
        </visual>
        <collision>
            <origin rpy="0 0 0" xyz="0 0 0"/>
            <geometry>
                <cylinder length="0.5e-3" radius="0.25e-3"/>
            </geometry>
        </collision>
    </link>
    <!-- joint Drive output -->
    <joint name="RF_KFE" type="revolute">
        <parent link="RF_KFE"/>
        <child link="RF_SHANK"/>
        <origin rpy="0 0 0" xyz="0 0 0"/>
        <axis xyz="0 0 1"/>
        <limit effort="80.0" velocity="20." lower="-0.2" upper="0.2"/>
        <dynamics damping="0.0" friction="0.0"/>
    </joint>
    <!-- Drive Output Link -->
    <link name="RF_SHANK">
        <visual>
            <origin rpy="0 0 0" xyz="0 0 0"/>
            <geometry>
                <cylinder length="0.5e-3" radius="0.25e-3"/>
            </geometry>
            <material name="Red">
                <color rgba="1.0 0.0 0.0 0.8"/>
            </material>
        </visual>
    </link>
    <joint name="RF_SHANK_RF_SHANK_fixed" type="fixed">
        <parent link="RF_SHANK"/>
        <child link="RF_SHANK_fixed"/>
        <origin rpy="0 0 1.5707963268" xyz="0 1.5e-3 0"/>
    </joint>
    <link name="RF_SHANK_fixed">
        <visual>
            <origin rpy="0 0 0" xyz="0 0 0"/>
            <geometry>
                <box size = "3e-3 1e-3 0.5e-3"/>
            </geometry>
            <material name="Blue">
                <color rgba="0.0 0.0 1.0 0.8"/>
            </material>
        </visual>
        <inertial>
            <origin rpy="0 0 0" xyz="0 0 0"/>
            <mass value="0.002e-9"/>
        <!-- <inertia 
            ixx="0.002e-9" 
            ixy="0" 
            ixz="0" 
            iyy="0.002e-9" 
            iyz="0" 
            izz="0.002e-9"/> -->
        </inertial>
    </link>
    <joint name="RF_SHANK_fixed_RF_Foot" type="fixed">
        <parent link="RF_SHANK_fixed"/>
        <child link="RF_Foot"/>
        <origin rpy="0 0 1.5707963268" xyz="1.5e-3 0 0"/>
    </joint>
    <link name="RF_Foot">
        <visual>
            <origin rpy="0 0 0" xyz="0 0 0"/>
            <geometry>
                <cylinder length="1e-3" radius="0.6e-3"/>
            </geometry>
            <material name="Red">
                <color rgba="1.0 0.0 0.0 0.8"/>
            </material>
        </visual>
        <collision>
            <origin rpy="0 0 0" xyz="0 0 0"/>
            <geometry>
                <cylinder length="1e-3" radius="0.6e-3"/>
            </geometry>
        </collision>
    </link>



    <!--              -->
    <!-- Right Hind Leg -->
    <!--              -->

    <!-- [rad] -->
    <!-- joint base HAA -->
    <joint name="base_RH_HFE" type="fixed">
        <parent link="base_right"/>
        <child link="RH_HFE"/>
        <origin rpy="0 0 2.9415926535" xyz="0.0065 0.0055 0.0145"/>
    </joint>
    <!-- [m] -->
    <!-- [A] -->
    <!-- Drive Input Link -->
    <link name="RH_HFE">
        <visual>
            <origin rpy="0 0 0" xyz="0 0 0"/>
            <geometry>
                <cylinder length="0.5e-3" radius="0.25e-3"/>
            </geometry>
            <material name="Red">
                <color rgba="1.0 0.0 0.0 1.0"/>
            </material>
        </visual>
    </link>
    <!-- joint Drive output -->
    <joint name="RH_HFE" type="revolute">
        <parent link="RH_HFE"/>
        <child link="RH_THIGH"/>
        <origin rpy="0 0 0" xyz="0 0 0"/>
        <axis xyz="0 0 1"/>
        <limit effort="80.0" velocity="20." lower="-0.2" upper="0.2"/>
        <dynamics damping="0.0" friction="0.0"/>
    </joint>
    <!-- Drive Output Link -->
    <link name="RH_THIGH">
        <visual>
            <origin rpy="0 0 0" xyz="0 0 0"/>
            <geometry>
                <cylinder length="0.5e-3" radius="0.25e-3"/>
            </geometry>
            <material name="Red">
                <color rgba="1.0 0.0 0.0 0.8"/>
            </material>
        </visual>
    </link>
    <joint name="RH_THIGH_RH_THIGH_fixed" type="fixed">
        <parent link="RH_THIGH"/>
        <child link="RH_THIGH_fixed"/>
        <origin rpy="0 0 1.5707963268" xyz="0 -1.5e-3 0"/>
    </joint>
    <link name="RH_THIGH_fixed">
        <visual>
            <origin rpy="0 0 0" xyz="0 0 0"/>
            <geometry>
                <box size = "3e-3 1e-3 0.5e-3"/>
            </geometry>
            <material name="Blue">
                <color rgba="0.0 0.0 1.0 0.8"/>
            </material>
        </visual>
        <inertial>
            <origin rpy="0 0 0" xyz="0 0 0"/>
            <mass value="0.002e-9"/>
        <!-- <inertia 
            ixx="0.002e-9" 
            ixy="0" 
            ixz="0" 
            iyy="0.002e-9" 
            iyz="0" 
            izz="0.002e-9"/> -->
        </inertial>
    </link>
    <joint name="RH_THIGH_fixed_RH_KFE" type="fixed">
        <parent link="RH_THIGH_fixed"/>
        <child link="RH_KFE"/>
        <origin rpy="0 0 2.61799387799" xyz="-1.5e-3 0 0"/>
    </joint>
    <!-- [m] -->
    <!-- [A] -->
    <!-- Drive Input Link -->
    <link name="RH_KFE">
        <visual>
            <origin rpy="0 0 0" xyz="0 0 0"/>
            <geometry>
                <cylinder length="0.5e-3" radius="0.25e-3"/>
            </geometry>
            <material name="Red">
                <color rgba="1.0 0.0 0.0 0.8"/>
            </material>
        </visual>
        <collision>
            <origin rpy="0 0 0" xyz="0 0 0"/>
            <geometry>
                <cylinder length="0.5e-3" radius="0.25e-3"/>
            </geometry>
        </collision>
    </link>
    <!-- joint Drive output -->
    <joint name="RH_KFE" type="revolute">
        <parent link="RH_KFE"/>
        <child link="RH_SHANK"/>
        <origin rpy="0 0 0" xyz="0 0 0"/>
        <axis xyz="0 0 1"/>
        <limit effort="80.0" velocity="20." lower="-0.2" upper="0.2"/>
        <dynamics damping="0.0" friction="0.0"/>
    </joint>
    <!-- Drive Output Link -->
    <link name="RH_SHANK">
        <visual>
            <origin rpy="0 0 0" xyz="0 0 0"/>
            <geometry>
                <cylinder length="0.5e-3" radius="0.25e-3"/>
            </geometry>
            <material name="Red">
                <color rgba="1.0 0.0 0.0 0.8"/>
            </material>
        </visual>
    </link>
    <joint name="RH_SHANK_RH_SHANK_fixed" type="fixed">
        <parent link="RH_SHANK"/>
        <child link="RH_SHANK_fixed"/>
        <origin rpy="0 0 1.5707963268" xyz="0 1.5e-3 0"/>
    </joint>
    <link name="RH_SHANK_fixed">
        <visual>
            <origin rpy="0 0 0" xyz="0 0 0"/>
            <geometry>
                <box size = "3e-3 1e-3 0.5e-3"/>
            </geometry>
            <material name="Blue">
                <color rgba="0.0 0.0 1.0 0.8"/>
            </material>
        </visual>
        <inertial>
            <origin rpy="0 0 0" xyz="0 0 0"/>
            <mass value="0.002e-9"/>
        <!-- <inertia 
            ixx="0.002e-9" 
            ixy="0" 
            ixz="0" 
            iyy="0.002e-9" 
            iyz="0" 
            izz="0.002e-9"/> -->
        </inertial>
    </link>
    <joint name="RH_SHANK_fixed_RH_Foot" type="fixed">
        <parent link="RH_SHANK_fixed"/>
        <child link="RH_Foot"/>
        <origin rpy="0 0 1.5707963268" xyz="1.5e-3 0 0"/>
    </joint>
    <link name="RH_Foot">
        <visual>
            <origin rpy="0 0 0" xyz="0 0 0"/>
            <geometry>
                <cylinder length="1e-3" radius="0.6e-3"/>
            </geometry>
            <material name="Red">
                <color rgba="1.0 0.0 0.0 0.8"/>
            </material>
        </visual>
        <collision>
            <origin rpy="0 0 0" xyz="0 0 0"/>
            <geometry>
                <cylinder length="1e-3" radius="0.6e-3"/>
            </geometry>
        </collision>
    </link>

</robot>
